[32m   INFO [35mtests.test_typical_u[0m CTX=test CTX_INT= test_typical_usage.py:44:test_typical_usage Message #1[0m
[37m  DEBUG [35mtests.test_typical_u[0m CTX=test CTX_INT=method test_typical_usage.py:52:method Message #2[0m
[31m  ERROR [35mtests.test_typical_u[0m CTX=test CTX_INT=method test_typical_usage.py:56:method Exception
Traceback (most recent call last):
  File "{module_path}", line 54, in method
    raise RuntimeError
RuntimeError

Locals at innermost frame:

{{'__logger_context': {{'ctx': 'test', 'ctx_internal': 'method'}},
 'log': {logger},
 'saved_logger': {logger}}}[0m
[32m   INFO [35mtests.test_typical_u[0m CTX=test CTX_INT= test_typical_usage.py:60:test_typical_usage Message #3[0m
